<mujoco>
  <compiler autolimits="true"/>

  <asset>
    <texture name="grid" type="2d" builtin="checker" width="512" height="512" rgb1=".1 .2 .3" rgb2=".2 .3 .4"/>
    <material name="grid" texture="grid" texrepeat="1 1" texuniform="true" reflectance=".2"/>
    <mesh name="chasis" scale=".001 .005 .01"
      vertex=" 10   10   10
              -10  10  10
               10  -10   10
               10  10  -10
               10 -10  -10
              -10   10 -10
              -10 -10  10
              0  -10 -10
              "/>
  </asset>

  <default>
    <joint damping=".03" actuatorfrcrange="-0.5 0.5"/>
    <default class="wheel">
      <geom type="cylinder" size=".06 .01" rgba=".5 .5 1 1" friction="1.0 0.05 0.05"/>
    </default>
    <default class="decor">
      <site type="box" rgba=".5 1 .5 1"/>
    </default>
  </default>

  <worldbody>
    <geom type="plane" size="30 30 .01" material="grid"/>
    <body name="car" pos="0 0 .07" euler="0 0 0">
      <freejoint/>
      <light name="top light" pos="0 0 2" mode="trackcom" diffuse=".5 .5 .5"/>
      <geom name="chasis" pos="-0.07 0 0.1" type="box" size="0.02 0.05 0.1" mass="0.1"/>
      <site name="accel_site" pos="-0.07 0 0.05" type="sphere" size="0.01"/>
      <site name="gyro_site" pos="-0.07 0 0.05" type="sphere" size="0.01"/>
      <body name="left wheel" pos="-.07 .06 0" zaxis="0 1 0">
        <joint name="left"/>
        <geom class="wheel"/>
        <site class="decor" size=".006 .025 .012"/>
        <site class="decor" size=".025 .006 .012"/>
      </body>
      <body name="right wheel" pos="-.07 -.06 0" zaxis="0 1 0">
        <joint name="right"/>
        <geom class="wheel"/>
        <site class="decor" size=".006 .025 .012"/>
        <site class="decor" size=".025 .006 .012"/>
      </body>
    </body>
  </worldbody>

  <tendon>
    <fixed name="forward">
      <joint joint="left" coef=".5"/>
      <joint joint="right" coef=".5"/>
    </fixed>
    <!-- <fixed name="turn">
      <joint joint="left" coef="-.5"/>
      <joint joint="right" coef=".5"/>
    </fixed> -->
  </tendon>

  <actuator>
    <motor name="forward" tendon="forward" ctrlrange="-1 1"/>
    <!-- <motor name="turn" tendon="turn" ctrlrange="-1 1"/> -->
  </actuator>

  <!-- <sensor>
    <jointactuatorfrc name="right" joint="right"/>
    <jointactuatorfrc name="left" joint="left"/>
  </sensor> -->

  <sensor>
        <accelerometer name="chassis_accel" site="accel_site"/>
        <gyro name="chassis_gyro" site="gyro_site"/>
  </sensor>
</mujoco>
